Workbook

Sheet Roster
A1: 2
A2: Total Cadets: | B2: =COUNTA(B4:B76) | C2: If you need to make a correction: | G2: If you are not on this roster at all use this link:
A3: Class | B3: Rank | C3: Last Name | D3: First Name | E3: MI | F3: Kent Email | G3: Crosstown Email | H3: Cell Phone | I3: School | J3: Major | K3: Assignment | L3: Position | M3: {={"SQ";IF(K57:K76 = "","",IFERROR(VLOOKUP(K57:K76,'Flight Linker'!A$1:C$17,2,FALSE),""))}} | N3: {={"GRP";IF(K57:K76 = "","",IFERROR(VLOOKUP(K57:K76,'Flight Linker'!A$1:C$17,3,FALSE),""))}} | O3: {={"flight position conc";K33:K76&" "&L33:L76}} | P3: {={"title conc";IF(C33:C85 = "","",B33:B76&" "&C33:C76)}} | Q3: {={"comma";IF(C33:C85 = "","",TRIM(Roster!$C33:C76&","&" "&Roster!$D33:D76))}} | R3: {={"semicol";IF(C33:C85 = "","",TRIM(Roster!$C33:C76&";"&" "&Roster!$D33:D76))}} | S3: alt llab
A4: AS100 | B4: C/4C | C4: Allen, Jr. | D4: Antonio | F4: fakeEmail@kent.edu | G4: fakeEmail@anotherSchool.edu | H4: 123.456.7890 | I4: YSU | P4: C/3C Babik | Q4: Babik, Thomas | R4: Babik; Thomas | S4: FALSE
A5: AS100 | B5: C/4C | C5: Cavaliere | D5: Ava | E5: C | F5: fakeEmail2@kent.edu | I5: KSU | P5: C/3C Bias | Q5: Bias, Derrick | R5: Bias; Derrick | S5: FALSE
A6: AS100 | B6: C/4C | C6: Cunningham | D6: Ph'Nique | F6: fakeEmail3@kent.edu | I6: KSU | P6: C/3C Choi | Q6: Choi, Joseph | R6: Choi; Joseph | S6: FALSE
A7: AS100 | B7: C/4C | C7: Davis | D7: Elexis | E7: J | F7: fakeEmail4@kent.edu | I7: UA | P7: C/3C Crim | Q7: Crim, Ryan | R7: Crim; Ryan | S7: FALSE
A8: AS100 | B8: C/4C | C8: Gale | D8: Charles | E8: D | F8: fakeEmail5@kent.edu | I8: KSU | J8: Computer Science | P8: C/3C Fields | Q8: Fields, Ava | R8: Fields; Ava | S8: FALSE
A9: AS100 | B9: C/4C | C9: Geraci | D9: Nicholas | F9: fakeEmail6@kent.edu | I9: UA | P9: C/3C Folger | Q9: Folger, Colin | R9: Folger; Colin | S9: FALSE
A10: AS100 | B10: C/4C | C10: Gould | D10: Noah | E10: I | F10: fakeEmail7@kent.edu | I10: KSU | J10: Enviromental Biology | P10: C/3C Loibl | Q10: Loibl, Lucas | R10: Loibl; Lucas | S10: FALSE
A11: AS100 | B11: C/4C | C11: Haggerty | D11: Anthony | F11: fakeEmail8@kent.edu | I11: KSU | P11: C/4C Marshall | Q11: Marshall, Natasha | R11: Marshall; Natasha | S11: FALSE
A12: AS100 | B12: C/4C | C12: Hodges | D12: Monica | F12: fakeEmail9@kent.edu | I12: KSU | P12: C/3C Matolyak | Q12: Matolyak, Bryce | R12: Matolyak; Bryce | S12: FALSE
A13: AS100 | B13: C/4C | C13: Howard | D13: Blake | F13: fakeEmail10@kent.edu | I13: KSU | P13: C/3C Page | Q13: Page, William | R13: Page; William | S13: FALSE
A14: AS100 | B14: C/4C | C14: Hughes | D14: James | E14: J | F14: fakeEmail11@kent.edu | I14: KSU | J14: Aerospace | P14: C/3C Roberts | Q14: Roberts, Caden | R14: Roberts; Caden | S14: FALSE
A15: AS100 | B15: C/4C | C15: Jackson | D15: Isaiah | F15: fakeEmail12@kent.edu | I15: KSU | P15: C/3C Roylo | Q15: Roylo, Kai | R15: Roylo; Kai | S15: FALSE
A16: AS100 | B16: C/4C | C16: Kalas | D16: James | E16: A | F16: fakeEmail13@kent.edu | I16: JCU | P16: C/3C Stewart | Q16: Stewart, Kayla | R16: Stewart; Kayla | S16: FALSE
A17: AS100 | B17: C/4C | C17: Knauer | D17: Emma | E17: I | F17: fakeEmail14@kent.edu | I17: KSU | J17: Psychology | P17: C/3C Stricker | Q17: Stricker, Johathan | R17: Stricker; Johathan | S17: FALSE
A18: AS100 | B18: C/4C | C18: Kotlarsic | D18: Gustav | E18: P | F18: fakeEmail15@kent.edu | I18: KSU | J18: Aerospace Engineering | P18: C/3C Valek | Q18: Valek, Justin | R18: Valek; Justin | S18: FALSE
A19: AS100 | B19: C/4C | C19: LaChapelle | D19: Tyler | E19: M | F19: fakeEmail16@kent.edu | I19: KSU | P19: C/3C Wall | Q19: Wall, Kalli | R19: Wall; Kalli | S19: FALSE
A20: AS100 | B20: C/4C | C20: McMannes | D20: Samantha | E20: M | F20: fakeEmail17@kent.edu | I20: KSU | P20: C/4C Mockel | Q20: Mockel, Ella | R20: Mockel; Ella | S20: FALSE
A21: AS100 | B21: C/4C | C21: Mohsin | D21: Yousif | E21: H | F21: fakeEmail18@kent.edu | I21: KSU | P21: C/3C Brass | Q21: Brass, Jacob | R21: Brass; Jacob | S21: FALSE
A22: AS100 | B22: C/4C | C22: Moore | D22: Jayland | F22: fakeEmail19@kent.edu | I22: KSU | P22: C/3C Pinson | Q22: Pinson, Mycah | R22: Pinson; Mycah | S22: FALSE
A23: AS100 | B23: C/4C | C23: Montie | D23: Bethany | F23: fakeEmail20@kent.edu | P23: C/3C Schriener | Q23: Schriener, Madalyn | R23: Schriener; Madalyn | S23: FALSE
A24: AS100 | B24: C/4C | C24: Peronek | D24: Joe | F24: fakeEmail21@kent.edu | I24: UA | P24: C/3C Soderstrom | Q24: Soderstrom, Kade | R24: Soderstrom; Kade | S24: FALSE
A25: AS100 | B25: C/4C | C25: Reyher | D25: Renee | F25: fakeEmail22@kent.edu | I25: UA | P25: C/Maj Boersma | Q25: Boersma, Paul | R25: Boersma; Paul | S25: FALSE
A26: AS100 | B26: C/4C | C26: Rosenberger | D26: Samuel | E26: J | F26: fakeEmail23@kent.edu | I26: KSU | P26: C/Capt Rueffel | Q26: Rueffel, Julien | R26: Rueffel; Julien | S26: FALSE
A27: AS100 | B27: C/4C | C27: Sabruno | D27: Hannah | F27: fakeEmail24@kent.edu | I27: KSU | J27: criminology | P27: C/Lt Col Woodford | Q27: Woodford, Aniliss | R27: Woodford; Aniliss | S27: FALSE
A28: AS100 | B28: C/4C | C28: Shamberger | D28: Hugo | E28: T | F28: fakeEmail25@kent.edu | I28: KSU | P28: C/Capt Carney | Q28: Carney, Reilly | R28: Carney; Reilly | S28: FALSE
A29: AS100 | B29: C/4C | C29: So-Gilmore | D29: Deja | F29: fakeEmail26@kent.edu | P29: C/Col Farah | Q29: Farah, Samantha | R29: Farah; Samantha | S29: FALSE
A30: AS100 | B30: C/4C | C30: Spalding | D30: Mya | E30: R | F30: fakeEmail27@kent.edu | I30: KSU | P30: C/Capt James | Q30: James, Joshua | R30: James; Joshua | S30: FALSE
A31: AS100 | B31: C/4C | C31: Vo | D31: Brandon | E31: H | F31: fakeEmail28@kent.edu | I31: CASE | P31: C/Maj Kim | Q31: Kim, Dohwan | R31: Kim; Dohwan | S31: FALSE
A32: AS100 | B32: C/4C | C32: Wayland | D32: Jesse | E32: M | F32: fakeEmail29@kent.edu | I32: KSU | P32: C/Capt Mackniak | Q32: Mackniak, Jacob | R32: Mackniak; Jacob | S32: FALSE
A33: AS200 | B33: C/3C | C33: Babik | D33: Thomas | E33: A | F33: fakeEmail30@kent.edu | I33: KSU | J33: Aerospace Engineering | P33: C/Capt Maleski | Q33: Maleski, Bryce | R33: Maleski; Bryce | S33: FALSE
A34: AS200 | B34: C/3C | C34: Bias | D34: Derrick | E34: J | F34: fakeEmail31@kent.edu | I34: KSU | J34: Aeronautics | P34: C/Capt McCullough | Q34: McCullough, Elyse | R34: McCullough; Elyse | S34: FALSE
A35: AS200 | B35: C/3C | C35: Choi | D35: Joseph | E35: K | F35: fakeEmail32@kent.edu | I35: KSU | J35: Computer Science | P35: C/Col Shutic | Q35: Shutic, Joshua | R35: Shutic; Joshua | S35: FALSE
A36: AS200 | B36: C/3C | C36: Crim | D36: Ryan | E36: M | F36: fakeEmail33@kent.edu | I36: UA | J36: Aerospace Engineering | P36: C/Capt Koromyslichenko | Q36: Koromyslichenko, Viktor | R36: Koromyslichenko; Viktor | S36: FALSE
A37: AS200 | B37: C/3C | C37: Fields | D37: Ava | E37: K | F37: fakeEmail34@kent.edu | I37: KSU | J37: Nursing | P37: C/Lt Col Howard | Q37: Howard, Eryn | R37: Howard; Eryn | S37: FALSE
A38: AS200 | B38: C/3C | C38: Folger | D38: Colin | E38: E | F38: fakeEmail35@kent.edu | I38: KSU | J38: Aeronautics PROP | P38: C/Lt Col AhSam-Kreiter | Q38: AhSam-Kreiter, Vincent | R38: AhSam-Kreiter; Vincent | S38: FALSE
A39: AS200 | B39: C/3C | C39: Loibl | D39: Lucas | E39: B | F39: fakeEmail36@kent.edu | I39: KSU | J39: Criminology & Justice | P39: C/Maj Armagno | Q39: Armagno, Giacomo | R39: Armagno; Giacomo | S39: FALSE
A40: AS200 | B40: C/4C | C40: Marshall | D40: Natasha | E40: C | F40: fakeEmail37@kent.edu | I40: KSU | J40: Finance | P40: C/Capt Billock | Q40: Billock, Madeline | R40: Billock; Madeline | S40: FALSE
...

Sheet Sheet30

Sheet Squadrons & Staff
A1: OSS | B1: OTS | C1: FSS | D1: LRS | E1: MWR | F1: FTPS | G1: Wing Staff | H1: Group Staff | I1: WIT | J1: Wing Staff | K1: CSS | L1: OG | M1: MSG | N1: TTG
A2: =IFERROR(__xludf.DUMMYFUNCTION("sort(iferror(FILTER(#REF!,Roster!$M:$M=A1),""""))"),"") | B2: =IFERROR(__xludf.DUMMYFUNCTION("sort(iferror(FILTER(#REF!,Roster!$M:$M=B1),""""))"),"") | C2: =IFERROR(__xludf.DUMMYFUNCTION("sort(iferror(FILTER(#REF!,Roster!$M:$M=C1),""""))"),"") | D2: =IFERROR(__xludf.DUMMYFUNCTION("sort(iferror(FILTER(#REF!,Roster!$M:$M=D1),""""))"),"") | E2: =IFERROR(__xludf.DUMMYFUNCTION("sort(iferror(FILTER(#REF!,Roster!$M:$M=E1),""""))"),"") | F2: =IFERROR(__xludf.DUMMYFUNCTION("sort(iferror(FILTER(#REF!,Roster!$M:$M=F1),""""))"),"") | G2: =IFERROR(__xludf.DUMMYFUNCTION("sort(filter({I2:I10;J2:J10;K2:K10},NOT(ISBLANK({I2:I10;J2:J10;K2:K10}))))"),"") | H2: =IFERROR(__xludf.DUMMYFUNCTION("sort(filter({L2:L10;M2:M10;N2:N10},NOT(ISBLANK({L2:L10;M2:M10;N2:N10}))))"),"") | I2: =IFERROR(__xludf.DUMMYFUNCTION("sort(iferror(FILTER(#REF!,Roster!$K:$K=I1),""""))"),"") | J2: =IFERROR(__xludf.DUMMYFUNCTION("sort(iferror(FILTER(#REF!,Roster!$K:$K=J1),""""))"),"") | K2: =IFERROR(__xludf.DUMMYFUNCTION("sort(iferror(FILTER(#REF!,Roster!$K:$K=K1),""""))"),"") | L2: =IFERROR(__xludf.DUMMYFUNCTION("sort(iferror(FILTER(#REF!,Roster!$K:$K=L1),""""))"),"") | M2: =IFERROR(__xludf.DUMMYFUNCTION("sort(iferror(FILTER(#REF!,Roster!$K:$K=M1),""""))"),"") | N2: =IFERROR(__xludf.DUMMYFUNCTION("sort(iferror(FILTER(#REF!,Roster!$K:$K=N1),""""))"),"")
G3: =IFERROR(__xludf.DUMMYFUNCTION("""COMPUTED_VALUE"""),"") | H3: =IFERROR(__xludf.DUMMYFUNCTION("""COMPUTED_VALUE"""),"")
G4: =IFERROR(__xludf.DUMMYFUNCTION("""COMPUTED_VALUE"""),"") | H4: =IFERROR(__xludf.DUMMYFUNCTION("""COMPUTED_VALUE"""),"")

Sheet Signature Sheet
A1: {={"";IF(TRIM(INDIRECT("Roster!O4:O"&B1)) <> "",TRIM(INDIRECT("Roster!D4:D"&B1))&" "&IFS(TRIM(INDIRECT("Roster!E4:E"&B1))="","",TRIM(INDIRECT("Roster!E4:E"&B1))="-","",TRIM(INDIRECT("Roster!E4:E"&B1))<>"",TRIM(INDIRECT("Roster!E4:E"&B1))&". ")&TRIM(INDIRECT("Roster!C4:C"&B1))&", "&INDIRECT("Roster!B4:B"&B1)&", AFROTC"&CHAR(10)&VLOOKUP(INDIRECT("Roster!I4:I"&B1),'Signature Backend'!A$1:B$9,2,0)&CHAR(10)&IFERROR(VLOOKUP(INDIRECT("Roster!O4:O"&B1),'Signature Backend'!A$11:B$185,2,FALSE),VLOOKUP(TRIM(INDIRECT("Roster!O4:O"&B1)),'Signature Backend'!A$10:B$185,2,FALSE))&CHAR(10)&LEFT(INDIRECT("Roster!H4:H"&B1),12),TRIM(INDIRECT("Roster!D4:D"&B1))&" "&TRIM(INDIRECT("Roster!C4:C"&B1))&CHAR(10)&"No flight assigned")}} | B1: =Roster!B2+3
A2: Antonio Allen, Jr. No flight assigned
A3: Ava Cavaliere No flight assigned
A4: Ph'Nique Cunningham No flight assigned
A5: Elexis Davis No flight assigned
A6: Charles Gale No flight assigned
A7: Nicholas Geraci No flight assigned
A8: Noah Gould No flight assigned
A9: Anthony Haggerty No flight assigned
A10: Monica Hodges No flight assigned
A11: Blake Howard No flight assigned
A12: James Hughes No flight assigned
A13: Isaiah Jackson No flight assigned
... A74: Malik Woodford No flight assigned

Sheet Changelog
A1: Date of change | B1: Description of change | C1: CSS Personel | D1: Date of change | E1: Description of change | F1: CSS Personel
A2: 42919 | B2: Removal of Biastre
A3: 42926 | B3: Removal of Nemeth and Moore
A4: 42926 | B4: Addition of Yammarino
A5: 42926 | B5: Changed Ludwig to safety
A6: 42926 | B6: Changed Rivera to PT
A7: 42926 | B7: Assigned Yammarino to PT
A8: 42928 | B8: Changed all fonts to Arial
A9: 42928 | B9: added sheet "Graphs"
A10: 42940 | B10: modified concanate sheet
A11: 42956 | B11: removal of Scott
A12: 42956 | B12: updated C/Wood's position
A13: 42962 | B13: Removal of Bayne
... A67: 43277 | B67: updated to fall 18
A68: 43279 | B68: drop c smith | C68: TKE
A69: 43279 | B69: C/Keenan moved to AS500 | C69: TKE
A70: 43279 | B70: C/Coler to POC LLAB CC, C/Flowers to PA CD | C70: TKE
A71: 43279 | B71: Reinstated Bowman | C71: TKE
A72: 43279 | B72: Schaffer to M&S | C72: TKE
A73: 43279 | B73: Lyons removed | C73: TKE
A74: 43279 | B74: Youngblood removed | C74: TKE
A75: 43296 | B75: Rediger added | C75: TKE
A76: 43309 | B76: Knight removed | C76: EDL
A77: 43313 | B77: Gilreath to POC LLAB | C77: EDL
A78: 43313 | B78: Rediger to MWR | C78: EDL
A79: 43314 | B79: Bowman, Dregley, and Fuller to C/2d Lt | C79: EDL
... A234: 43832 | B234: Drop: Flowers | C234: HWS
D235: 43850 | E235: Start of Spring 2020 | F235: ZTK
D236: 43850 | E236: Updated Chain of Command | F236: ZTK
D237: 43850 | E237: Updated and fixed Signature Blocks | F237: ZTK
D238: 43850 | E238: Add: Beardsley, Horton, Sivy, Bardwell, Gilchrist, Sawyer, Sylvester, ZImmerman | F238: TAS
D239: 43850 | E239: Drop: Caconico, Mosley | F239: TAS
D240: 43851 | E240: Drop: Doyle, Patterson, Toomer, Larson, Byrd | F240: TAS
D241: 43851 | E241: Drop: Holswade, Lauren; Knight, Zachary | F241: DJS
D242: 43853 | E242: Drop: Gilson | F242: TAS
D243: 43853 | E243: Move: Allison to Supply CC, Parker to Academics CC | F243: TAS
D244: 43857 | E244: Drop: Tosti | F244: TAS
D245: 43857 | E245: Move: Spencer to 200 | F245: TAS
D246: 43868 | E246: Drop: Peace, Syx, Terleckyj | F246: DJS
D247: 43894 | E247: Move: Gardner to FSS CC, Orcutt to OSS CD | F247: TAS
...

Sheet New Cadet QR
A12: Scan and fill this out ------->

Sheet correction qr

Sheet New Cadet input
A1: Timestamp | B1: Email Address | C1: What is your last name? | D1: What is your first name? | E1: What is your middle initial? | F1: What is your school email? | G1: What is your cell phone number? | H1: What school do you attend? | I1: What is your major? | J1: What is your Flight? | K1: Initials of CSS personel | L1: Date updated(Ctrl+semicolon for current date)
A2: 42891.45 | B2: nmalacho@kent.edu | C2: Malachowski | D2: Nicholas | E2: D | F2: nmalacho@kent.edu | G2: 5857471128 | H2: KSU | I2: Aeronautics | K2: ss | L2: 42894
A3: 42969.672 | B3: mattchamberlain97@gmail.com | C3: Chamberlain | D3: Matthew | E3: J. | F3: mchamb23@kent.edu | G3: 2347361450 | H3: KSU | I3: History | K3: ss | L3: 42981
A4: 42970.56 | B4: tke819@gmail.com | C4: Evans | D4: Tyler | E4: K | F4: tevans44@kent.edu | G4: 5619510426 | H4: KSU | I4: Russian Literature; Culture and Translation | K4: ss | L4: 42970
A5: 42970.569 | B5: awsoftball2@aol.com | C5: Wilson | D5: Alexandria | E5: E | F5: awils140@kent.edu | G5: 3308585728 | H5: KSU | I5: Criminal justice studies | K5: ss | L5: 42970
A6: 42970.57 | B6: laurenburkhard2017@gmail.com | C6: Burkhard | D6: Lauren | E6: B | F6: lburkha6@kent.edu | G6: 2345677544 | H6: KSU | I6: Pre medicine | K6: ss | L6: 42970
A7: 42970.573 | B7: jsheri4@kent.edu | C7: Sherrill | D7: Justin | E7: A | F7: jsheri4@kent.edu | G7: 4403965306 | H7: KSU | I7: Computer Information System | K7: ss | L7: 42970
A8: 42970.574 | B8: creed48@kent.edu | C8: Reed | D8: Colleen | E8: M | F8: creed48@kent.edu | G8: 4405961780 | H8: KSU | I8: Nursing | K8: ss | L8: 42970
A9: 42970.577 | B9: jgrant29@kent.edu | C9: Grant | D9: Jacob | E9: P | F9: jgrant29@kent.edu | G9: 4197068933 | H9: KSU | I9: Aerospace Engineering | K9: ss | L9: 42970
A10: 42970.578 | B10: jmw363@zips.uakron.edu | C10: Walker | D10: Jordan | E10: M | F10: jmw363@zips.uakron.edu | G10: 3305755264 | H10: UA | I10: Aerospace Systems Engineering | K10: ss | L10: 42970
A11: 42970.578 | B11: chrich@kent.edu | C11: Hrich | D11: Christopher | E11: D | F11: chrich@kent.edu | G11: 4405912616 | H11: KSU | I11: Computer Science | K11: ss | L11: 42970
A12: 42970.578 | B12: cmarowsk@kent.edu | C12: Marowski | D12: Clayton | E12: P | F12: cmarowsk@kent.edu | G12: 3172137829 | H12: KSU | I12: Flight Technology | K12: ss | L12: 42970
A13: 42970.578 | B13: jkeenan8@kent.edu | C13: Keenan | D13: Julia | E13: E | F13: jkeenan8@kent.edu | G13: 9372672178 | H13: KSU | I13: Hospitality Management | K13: ss | L13: 42970
... A59: 42978.757 | B59: jacksonrev@aol.com | C59: Jackson | D59: Kevin | E59: A | F59: kevin.a.jackson75.mil@mail.mil | G59: 3015186954 | H59: CSU | I59: Health sciences | K59: ss | L59: 42981
A60: 42980.124 | B60: dwils110@kent.edu | C60: Wilson | D60: Dajanae | E60: D | F60: dwils110@kent.edu | G60: 2166007220 | H60: KSU | I60: Biology Pre-Medical Pre-Dental | J60: I don't know what my flight is | K60: ss | L60: 42981
A61: 42980.405 | B61: apero@kent.edu | C61: Pero | D61: Austin | E61: W | F61: apero@kent.edu | G61: 3306052613 | H61: KSU | I61: Architecture | J61: CSS Flight | K61: ss | L61: 42981
A62: 42981.47 | B62: jfowle17@kent.edu | C62: Fowler | D62: Jordan | E62: J | F62: jfowle17@kent.edu | G62: 3302404084 | H62: KSU | I62: Aeronautics | J62: Alt LLAB Flight | K62: ss | L62: 42981
A63: 42983.401 | B63: Dander60@kent.edu | C63: Anderson | D63: Dylan | E63: T | F63: Dander60@kent.edu | G63: 4014641371 | H63: KSU | I63: Aerospace Engineering | J63: I don't know what my flight is | K63: ss | L63: 42983
A64: 42985.747 | B64: mirandaljones99@gmail.com | C64: Jones | D64: Miranda | E64: L | F64: mjone217@kent.edu | G64: 2343083135 | H64: KSU | I64: Computer Science | J64: LLAB Flight | K64: ss | L64: 42985
A65: 42989.402 | B65: jhk15@zips.uakron.edu | C65: Klebe | D65: Johnathon | E65: H | F65: jhk15@zips.uakron.edu | G65: 4403917307 | H65: UA | I65: Mechanical Enguneering | J65: Option 13 | K65: ss | L65: 42989
A66: 43118.733 | B66: cyoungbl17@mail.bw.edu | C66: Youngblood | D66: Caleb | E66: M | F66: cyoungbl17@mail.bw.edu | G66: 8138339010 | H66: BW | I66: Criminal justice | J66: I don't know what my flight is | K66: tdb | L66: 43118
A67: 43118.734 | B67: hkim32@gmail.com | C67: Kim | D67: Hyeokjin | E67: N | F67: hkim32@gmail.com | G67: 2342637149 | H67: KSU | I67: Aeronautics | J67: LLAB Flight | K67: tdb | L67: 43118
A68: 43118.884 | B68: tschaff2@kent.edu | C68: Schaffer | D68: Travis | E68: A | F68: tschaff2@kent.edu | G68: 3305023368 | H68: KSU | I68: Nursing | J68: POC LLAB Flight | K68: tdb | L68: 43118
A69: 43119.298 | B69: clk107@zips.uakron.edu | C69: Knight | D69: Connor | E69: L | F69: clk107@zips.uakron.edu | G69: 3304192640 | H69: UA | I69: Mechanical Engineering | J69: PA Flight | K69: tdb | L69: 43119
A70: 43119.455 | B70: brankine@kent.edu | C70: Rankine | D70: Brock | E70: D | F70: brankine@kent.edu | G70: 4197500162 | H70: KSU | I70: Aeronautics | J70: PT Flight | K70: tdb | L70: 43119
A71: 43119.497 | B71: eliebold@kent.edu | C71: Liebold | D71: Erin | E71: D | F71: eliebold@kent.edu | G71: 4127797453 | H71: KSU | I71: Aeronautical Systems Engineering Technology | J71: I don't know what my flight is | K71: tdb | L71: 43119
... A93: 43333.361 | B93: ashtonwright33@hotmail.com | C93: Wright | D93: Ashton | E93: P | F93: awrigh81@kent.edu | G93: 3304418433 | H93: KSU | I93: Flight tech | J93: I don't know what my flight is | K93: SS | L93: 43333
A94: 43333.362 | B94: koppgarrett5@gmail.com | C94: Kopp | D94: Garrett | E94: M | F94: g.m.kopp@vikes.csuohio.edi | H94: CSU | I94: Accounting | J94: I don't know what my flight is | K94: SS | L94: 43333
A95: 43333.362 | B95: LZimme13@Kent.edu | C95: Zimmerman | D95: Lance | E95: A | F95: LZimme13@kent.edu | G95: 3306214902 | H95: KSU | I95: Political Science and Russian | J95: I don't know what my flight is | K95: SS | L95: 43333
A96: 43333.362 | B96: joseph.winfrey@gmail.com | C96: Winfrey | D96: Joseph | E96: M | F96: jwinfrey@kent.edu | G96: 4109785762 | H96: KSU | I96: Criminology | J96: I don't know what my flight is | K96: SS | L96: 43333
A97: 43333.363 | B97: sorvillo28@hotmail.com | C97: sorvillo | D97: kaylee | E97: a | F97: ksorvill@kent.edu | G97: 3303983629 | H97: KSU | I97: exploratory | J97: I don't know what my flight is | K97: SS | L97: 43333
A98: 43333.363 | B98: gabbertlogan@gmail.com | C98: Gabbert | D98: Logan | E98: A | F98: lgabber1@kent.edu | G98: 9897430089 | H98: KSU | I98: International Relations/Global Studies | J98: I don't know what my flight is | K98: SS | L98: 43333
A99: 43333.363 | B99: pfosbrin@kent.edu | C99: Fosbrink | D99: Patrick | F99: pfosbrin@kent.edu | G99: 7577935756 | H99: KSU | I99: English | J99: I don't know what my flight is | K99: SS | L99: 43333
A100: 43333.364 | B100: sneuman@kent.edu | C100: Neuman | D100: Seamus | E100: O | F100: sneuman@kent.edu | G100: 4408657512 | H100: KSU | I100: Aeronautics | J100: I don't know what my flight is | K100: SS | L100: 43333
A101: 43333.364 | B101: pbrunell@kent.edu | C101: Brunell | D101: Paul | E101: J | F101: pbrunell@kent.edu | G101: 4403445249 | H101: KSU | I101: Computer Science | J101: I don't know what my flight is | K101: SS | L101: 43333
A102: 43333.365 | B102: dejaznaparr@gmail.com | C102: Littlejohn | D102: Dejazna | E102: M | F102: littlejohnd@hiram.edu | G102: 2165562222 | H102: HC | I102: Political science | J102: I don't know what my flight is | K102: SS | L102: 43333
A103: 43333.365 | B103: heidihowell1999@yahoo.com | C103: Howell | D103: Heidi | E103: L | F103: hhowell3@kent.edu | G103: 5137639375 | H103: KSU | I103: Criminal justice | J103: I don't know what my flight is | K103: SS | L103: 43333
A104: 43333.365 | B104: sbrawle3@kent.edu | C104: Brawley | D104: Samuel | E104: D | F104: sbrawle3@kent.edu | G104: 8045430982 | H104: KSU | I104: Architecturual studies | J104: I don't know what my flight is | K104: SS | L104: 43333
A105: 43333.366 | B105: hparker9@kent.edu | C105: Parker | D105: Hannah | E105: M | F105: hparker9@kent.edu | G105: 3304164151 | H105: KSU | I105: Business | J105: I don't know what my flight is | K105: SS | L105: 43333
A106: 43333.366 | B106: hgoodma3@kent.edu | C106: Goodman | D106: Hannah | E106: L | F106: hgoodma3@kent.edu | G106: 7407081836 | H106: KSU | I106: undecided | J106: I don't know what my flight is | K106: SS | L106: 43333
...

Sheet Correction request input
A1: Timestamp | B1: Email Address | C1: What is your last name | D1: What is your first name | E1: Select what you need corrected | F1: Type the corrected entry | G1: Type the corrected entry | H1: Type the corrected entry | K1: Select your correct position | L1: Select your School | P1: Initials of CSS personel | Q1: Date updated(Ctrl+semicolon for current date)
A2: 43466.731 | B2: tsmit216@kent.edu | C2: Smith | E2: Major | F2: Criminology and Justice Studies, Psychology | P2: ZTK | Q2: 43476
A3: 43467.675 | B3: clarisse@kent.edu | C3: Larissey | E3: Email | G3: clarissey@kent.edu | P3: MAC | Q3: 43476
A4: 43467.675 | B4: clarisse@kent.edu | C4: Larissey | E4: Email | G4: clarisse@kent.edu | P4: MAC | Q4: 43476
A5: 43467.675 | B5: clarisse@kent.edu | C5: Larissey | E5: School | L5: KSU | P5: MAC | Q5: 43476
A6: 43467.676 | B6: clarisse@kent.edu | C6: Larissey | E6: Assignment | M6: PA Flight | P6: MAC | Q6: 43476
A7: 43472.541 | B7: egilreat17@bw.edu | C7: Gilreath | E7: Email | G7: egilreat17@bw.edu | P7: ZTK | Q7: 43476
A8: 43482.566 | B8: vkill@kent.edu | C8: Kill | E8: Major | F8: Environmental and Conservation Biology | P8: MAC | Q8: 43483
A9: 43488.418 | B9: sstrebl1@kent.edu | C9: Gilson | E9: Class | J9: 200 | P9: MAC | Q9: 43507
A10: 43543.809 | B10: sstrebl1@kent.edu | C10: Strebler | E10: Phone | H10: 9132465324 | P10: MAC | Q10: 43543
A11: 43573.623 | B11: sstrebl1@kent.edu | C11: Strebler | E11: Phone | H11: 3309409193 | P11: MAC | Q11: 43576
A12: 43701.483 | B12: ach111@zips.uakron.edu | C12: Hill | E12: Class | J12: 100 | P12: HWS | Q12: 43707
A13: 43701.484 | B13: ach111@zips.uakron.edu | C13: Hill | E13: Email | G13: ach111@zips.uakron.edu | P13: HWS | Q13: 43707
A14: 43701.488 | B14: ach111@zips.uakron.edu | C14: Hill | E14: Major | F14: Mechanical Engineering | P14: HWS | Q14: 43707
A15: 43707.684 | B15: djcampana@student.ysu.edu | C15: Campana | E15: Major | F15: Exercise Science | P15: HWS | Q15: 43711
A16: 43707.689 | B16: erikrichardson1001@gmail.com | C16: Richardson | E16: Phone | H16: 7243724882 | P16: HWS | Q16: 43711
A17: 43707.765 | B17: dromig3@kent.edu | C17: Romig | E17: Class | J17: 250 | P17: HWS | Q17: 43711
A18: 43708.419 | B18: tsmit216@kent.edu | C18: Smith | E18: Major | F18: Criminology and Justice Studies, Sociology | P18: HWS | Q18: 43711
A19: 43709.958 | B19: rforkapa@ofcs.net | C19: forkapa | E19: Phone | H19: 4407422479 | P19: HWS | Q19: 43711
A20: 43710.445 | B20: amurcko@kent.edu | C20: Murcko | E20: School | L20: KSU | P20: HWS | Q20: 43711
A21: 43710.446 | B21: amurcko@kent.edu | C21: Murcko | E21: Email | G21: amurcko@kent.edu | P21: HWS | Q21: 43711
A22: 43730.618 | B22: tschaff2@kent.edu | C22: Travis Schaffer | E22: Major | F22: Nursing | P22: HWS | Q22: 43745
A23: 43732.339 | B23: dromig3@kent.edu | C23: Romig | E23: Class | J23: 250 | P23: HWS | Q23: 43745
A24: 43734.607 | B24: lholswad@kent.edu | C24: Holswade | E24: Class | J24: 100 | P24: HWS | Q24: 43745
A25: 43782.669 | B25: mpasto10@kent.edu | C25: Pastore | E25: Major | F25: Aeronautical Studies | P25: TAS | Q25: 43843
A26: 43791.398 | B26: naorcutt@student.ysu.edu | C26: Orcutt | E26: Major | F26: Information Technology | P26: TAS | Q26: 43843
A27: 43838.645 | B27: d.daugherty5@cmlaw.csuohio.edu | C27: Daugherty | E27: Email | G27: bike.daugherty@gmail.com | P27: TAS | Q27: 43843
A28: 43857.679 | B28: mspenc40@kent.edu | C28: Spencer | E28: Class | J28: 200 | P28: TAS | Q28: 43857
A29: 43859.445 | B29: jdurant3@kent.edu | C29: Durant | E29: Major | F29: Exercise Science | P29: TAS | Q29: 43859
A30: 43986.803 | B30: lgabber1@kent.edu | C30: Gabbert | E30: Major | F30: Economics | P30: NPK | Q30: 44057
A31: 43992.591 | B31: pbrunell@kent.edu | C31: Brunell | E31: Major | F31: Mathematics | P31: NPK | Q31: 44057
A32: 44029.505 | B32: hwareham@kent.edu | C32: Wareham | E32: Phone | H32: 3302822521 | P32: NPK | Q32: 44057
A33: 44029.505 | B33: hwareham@kent.edu | C33: Wareham | E33: Major | F33: French Translation | P33: NPK | Q33: 44057
A34: 44038.833 | B34: pbrunell@kent.edu | C34: Brunell | E34: Major | F34: Mathematics | P34: NPK | Q34: 44057
A63: 43466.731 | B63: tsmit216@kent.edu | C63: Smith | E63: Major | F63: Criminology and Justice Studies, Psychology | P63: ZTK | Q63: 43476
A64: 43467.675 | B64: clarisse@kent.edu | C64: Larissey | E64: Email | G64: clarissey@kent.edu | P64: MAC | Q64: 43476
A65: 43467.675 | B65: clarisse@kent.edu | C65: Larissey | E65: Email | G65: clarisse@kent.edu | P65: MAC | Q65: 43476
A66: 43467.675 | B66: clarisse@kent.edu | C66: Larissey | E66: School | L66: KSU | P66: MAC | Q66: 43476
A67: 43467.676 | B67: clarisse@kent.edu | C67: Larissey | E67: Assignment | M67: PA Flight | P67: MAC | Q67: 43476
A68: 43472.541 | B68: egilreat17@bw.edu | C68: Gilreath | E68: Email | G68: egilreat17@bw.edu | P68: ZTK | Q68: 43476
...

Sheet Signature Backend
A1: KSU | B1: Kent State University
A2: UA | B2: University of Akron | J2: Architecturual Studies | K2: =PROPER(J2)
A3: CSU | B3: Cleveland State University | F3: CC | G3: CD | J3: Computer Science | K3: =PROPER(J3)
A4: BW | B4: Baldwin Walace University | E4: LLAB Flight | F4: =CONCATENATE($E4," ",F$3) | G4: =CONCATENATE($E4," ",G$3) | J4: Applied Engineering | K4: =PROPER(J4)
A5: CASE | B5: Case Western Reserve University | E5: PT Flight | F5: =CONCATENATE($E5," ",F$3) | G5: =CONCATENATE($E5," ",G$3) | J5: National security | K5: =PROPER(J5)
A6: YSU | B6: Youngstown State University | E6: POC LLAB Flight | F6: =CONCATENATE($E6," ",F$3) | G6: =CONCATENATE($E6," ",G$3) | J6: Aeronautics | K6: =PROPER(J6) | N6: =CONCATENATE(K2,",",K3,",",K4)
A7: HC | B7: Hiram College | E7: FTP Flight | F7: =CONCATENATE($E7," ",F$3) | G7: =CONCATENATE($E7," ",G$3) | J7: Aeronautical Studies | K7: =PROPER(J7)
A8: MU | B8: Mount Union University | E8: Alt LLAB Flight | F8: =CONCATENATE($E8," ",F$3) | G8: =CONCATENATE($E8," ",G$3) | J8: Civil Engineering | K8: =PROPER(J8)
A9: LCCC | B9: Lorain County Community College | E9: SP Flight | F9: =CONCATENATE($E9," ",F$3) | G9: =CONCATENATE($E9," ",G$3) | J9: Flight Technology | K9: =PROPER(J9)
A10: WU | B10: Walsh University | E10: Safety Flight | F10: =CONCATENATE($E10," ",F$3) | G10: =CONCATENATE($E10," ",G$3) | J10: Athletic Training | K10: =PROPER(J10)
A11: LLAB Flight CC | B11: LLAB Flight Commander | E11: FF Flight | F11: =CONCATENATE($E11," ",F$3) | G11: =CONCATENATE($E11," ",G$3) | J11: Political science | K11: =PROPER(J11)
A12: D&C Flight CC | B12: Drill and Ceremonies Flight Commander | E12: Supply Flight | F12: =CONCATENATE($E12," ",F$3) | G12: =CONCATENATE($E12," ",G$3) | J12: International Relations/Global Studies | K12: =PROPER(J12)
A13: PT Flight CC | B13: PT Flight Commander | E13: Heritage Flight | F13: =CONCATENATE($E13," ",F$3) | G13: =CONCATENATE($E13," ",G$3) | J13: Criminology | K13: =PROPER(J13)
A14: Heritage Flight CC | B14: Heritage Flight Commander | E14: CSS | F14: =CONCATENATE($E14," ",F$3) | G14: =CONCATENATE($E14," ",G$3) | J14: Mechanical Engineering | K14: =PROPER(J14)
A15: POC LLAB Flight CC | B15: POC LLAB Flight Commander | E15: Color Guard Flight | F15: =CONCATENATE($E15," ",F$3) | G15: =CONCATENATE($E15," ",G$3) | J15: Aeronautics | K15: =PROPER(J15)
A16: FF Flight CC | B16: Fighting Flashes Flight Commander | E16: Academics Flight | F16: =CONCATENATE($E16," ",F$3) | G16: =CONCATENATE($E16," ",G$3) | J16: Aeronautics | K16: =PROPER(J16)
A17: FTP CC | B17: FTP Commander | E17: Service Flight | F17: =CONCATENATE($E17," ",F$3) | G17: =CONCATENATE($E17," ",G$3) | J17: undecided | K17: =PROPER(J17)
A18: Alt LLAB Flight CC | B18: Alt LLAB Flight Commander | E18: PA Flight | F18: =CONCATENATE($E18," ",F$3) | G18: =CONCATENATE($E18," ",G$3) | J18: Aeronautics | K18: =PROPER(J18)
... A27: Recruiting Flight CC | B27: Recruiting Services Flight Commander | E27: SOF+POC LLAB | F27: =CONCATENATE($E27," ",F$3) | G27: =CONCATENATE($E27," ",G$3) | J27: Accounting | K27: =PROPER(J27)
A28: LRS CC | B28: Logistics Readiness Squadron Commander | F28: =CONCATENATE($E28," ",F$3) | J28: Business Management | K28: =PROPER(J28)
A29: OSS CC | B29: Operations Support Squadron Commander | F29: =CONCATENATE($E29," ",F$3) | J29: Transferring to Kent for aviation science | K29: =PROPER(J29)
A30: OTS CC | B30: Operations Training Squadron Commander | F30: =CONCATENATE($E30," ",F$3) | J30: Mechanical Engineering | K30: =PROPER(J30)
A31: FSS CC | B31: Force Support Squadron Commander | F31: =CONCATENATE($E31," ",F$3) | J31: Political science | K31: =PROPER(J31)
A32: OG CC | B32: Operations Group Commander | F32: =CONCATENATE($E32," ",F$3) | J32: Psychology | K32: =PROPER(J32)
A33: MSG CC | B33: Mission Support Group Commander | F33: =CONCATENATE($E33," ",F$3) | J33: Aeronautics | K33: =PROPER(J33)
A34: LLAB Flight CD | B34: LLAB Flight Deputy Commander | F34: =CONCATENATE($E34," ",F$3) | J34: Aeronautics | K34: =PROPER(J34)
A35: Heritage Flight CD | B35: Heritage Flight Deputy Commander | F35: =CONCATENATE($E35," ",F$3) | J35: Aeronautics | K35: =PROPER(J35)
A36: FF Flight CD | B36: Fighting Flashes Flight Deputy Commander | F36: =CONCATENATE($E36," ",F$3) | J36: Aeronautics (Air Traffic Control) | K36: =PROPER(J36)
A37: PT Flight CD | B37: Physical Training Flight Deputy Commander | F37: =CONCATENATE($E37," ",F$3) | J37: Chemical Engineering | K37: =PROPER(J37)
A38: POC LLAB Flight CD | B38: POC LLAB Flight Deputy Commander | F38: =CONCATENATE($E38," ",F$3) | J38: Criminology | K38: =PROPER(J38)
A39: D&C Flight CD | B39: Drill and Ceremonies Flight Deputy Commander | F39: =CONCATENATE($E39," ",F$3) | J39: Aerospace engineering | K39: =PROPER(J39)
... A49: Morale Flight CD | B49: Morale Flight Deputy Commander | F49: =CONCATENATE($E49," ",F$3) | J49: Sales Management | K49: =PROPER(J49)
A50: Recruiting Flight CD | B50: Recruiting Services Flight Deputy Commander | J50: Information systems | K50: =PROPER(J50)
A51: LRS CD | B51: Logistics Readiness Squadron Deputy Commander | J51: Criminology | K51: =PROPER(J51)
A52: OSS CD | B52: Operations Support Squadron Deputy Commander | J52: Political Science | K52: =PROPER(J52)
A53: OTS CD | B53: Operations Training Squadron Deputy Commander | J53: exploratory | K53: =PROPER(J53)
A54: FSS CD | B54: Force Support Squadron Deputy Commander | J54: Aeronautic studies | K54: =PROPER(J54)
A55: OG CD | B55: Operations Group Deputy Commander | J55: Criminology and Justice studies | K55: =PROPER(J55)
A56: MSG CD | B56: Mission Support Group Deputy Commander | J56: Criminology | K56: =PROPER(J56)
A57: LLAB Flight | B57: LLAB Flight | J57: Applied physics | K57: =PROPER(J57)
...

Sheet Flight Linker
A1: LLAB Flight | B1: OTS | C1: OG
A2: PT Flight | B2: OTS | C2: OG
A3: FTP | B3: OTS | C3: OG
A4: SOF+POC LLAB Flight | B4: OSS | C4: OG
A5: D&C Flight | B5: OSS | C5: OG
A6: Supply Flight | B6: FSS | C6: MSG
A7: Service+FF Flight | B7: FSS | C7: MSG
A8: PA Flight | B8: FSS | C8: MSG
A9: Recruiting Flight | B9: LRS | C9: MSG
A10: Academics+SP Flight | B10: LRS | C10: MSG
A11: Morale+Heritage Flight | B11: LRS | C11: MSG
A12: OTS | B12: OTS | C12: OG
... A15: FSS | B15: FSS | C15: MSG
A16: OG | C16: OG
A17: MSG | C17: MSG
B18: TTG | C18: TTG
B19: LLAB Flight | C19: OG
B20: VLLAB Flight | C20: OG
B21: POC LLAB Flight | C21: OG
B22: PT Flight | C22: OG
B23: Academics Flight | C23: OG
B24: Alt LLAB Flight | C24: OG
B25: Supply Flight | C25: MSG
B26: Service Flight | C26: MSG
B27: FF Flight | C27: MSG
B28: PA Flight | C28: MSG
B29: D&C Flight | C29: MSG
... B35: Bravo Flight | C35: TTG

Sheet Data Validation
A1: Class | B1: Ranks | C1: School
A2: AS100 | B2: C/4C | C2: KSU
A3: AS200 | B3: C/3C | C3: UA
A4: AS250 | B4: C/2d Lt | C4: CSU
A5: AS300 | B5: C/1st Lt | C5: BW
A6: AS400 | B6: C/Capt | C6: CASE
A7: AS500 | B7: C/Maj | C7: YSU
A8: AS700 | B8: C/Lt Col | C8: HC
A9: AS800 | B9: C/Col | C9: MU
A10: P | B10: - | C10: LCCC
C11: WU
